<?xml version="1.0" ?>
<robot xmlns:xacro="http://www.ros.org/wiki/xacro">

  <xacro:include filename="material.xacro" />

  <!-- base link -->

  <link name="base_link">
    <visual>
      <origin xyz="0 0 0.0975" rpy="0 0 0" />
      <geometry>
        <box size="0.27 0.185 0.055" />
      </geometry>
      <material name="white" />
    </visual>
  </link>

  <!-- left rear wheel -->

  <joint name="left_wheel_joint" type="continuous">
    <origin xyz="-0.085 0.0975 0.0375" rpy="${pi/2} 0 0" />
    <parent link="base_link" />
    <child link="left_wheel_link" />
    <axis xyz="0 1 0" />
  </joint>

  <link name="left_wheel_link">
    <visual>
      <origin xyz="0 0 0" rpy="0 0 0" />
      <geometry>
        <cylinder radius="0.0375" length="0.03" />
      </geometry>
      <material name="black" />
    </visual>
  </link>

  <!-- right rear wheel -->

  <joint name="right_wheel_joint" type="continuous">
    <origin xyz="-0.085 -0.0975 0.0375" rpy="${pi/2} 0 0" />
    <parent link="base_link" />
    <child link="right_wheel_link" />
    <axis xyz="0 1 0" />
  </joint>

  <link name="right_wheel_link">
    <visual>
      <origin xyz="0 0 0" rpy="0 0 0" />
      <geometry>
        <cylinder radius="0.0375" length="0.03" />
      </geometry>
      <material name="black" />
    </visual>
  </link>

  <!-- left front wheel -->
  <joint name="left_front_joint" type="continuous">
    <origin xyz="0.085 0.0975 0.0375" rpy="${pi/2} 0 0" />
    <parent link="base_link" />
    <child link="left_front_link" />
    <axis xyz="0 1 0" />
  </joint>

  <link name="left_front_link">
    <visual>
      <origin xyz="0 0 0" rpy="0 0 0" />
      <geometry>
        <cylinder radius="0.0375" length="0.03" />
      </geometry>
      <material name="black" />
    </visual>
  </link>

  <!-- right front wheel -->
  <joint name="right_front_joint" type="continuous">
    <origin xyz="0.085 -0.0975 0.0375" rpy="${pi/2} 0 0" />
    <parent link="base_link" />
    <child link="right_front_link" />
    <axis xyz="0 1 0" />
  </joint>

  <link name="right_front_link">
    <visual>
      <origin xyz="0 0 0" rpy="0 0 0" />
      <geometry>
        <cylinder radius="0.0375" length="0.03" />
      </geometry>
      <material name="black" />
    </visual>
  </link>
  
</robot>